Workbook

Sheet Introductory notes and summary
A1: Scores | B1: Description | C1: N° of papers | D1: Available | E1: Screening | G1: ToT papers | H1: Discarded | I1: Selected | J1: ToT Eligible | M1: Scores | N1: Description | O1: N° of papers Eligible | P1: Discarded | Q1: Included | R1: Eligibility | U1: Eligible papers | V1: Included papers
A2: 1 | B2: Papers focused on examples or approaches or method of cyber-attacks (DDOS, jamming, spoofing, etc) in AAM. These papers provide at least an introduction on cyberattacks in AAM. | C2: =COUNTIF(Selected_papers!B:B,"1") -> 152 | D2: =COUNTIFS(Selected_papers!A:A, "Y",Selected_papers!B:B, 1) -> 134 | G2: =COUNTIF(Selected_papers!C:C,"Y")+COUNTIF(Selected_papers!C:C,"N") -> 736 | H2: =COUNTIF(Selected_papers!C:C,"N") -> 487 | I2: =COUNTIF(Selected_papers!C:C,"Y") -> 249 | J2: =COUNTIF(Selected_papers!A:A,"Y") -> 224 | M2: 1 | N2: Papers focused on examples or approaches or method of cyber-attacks (DDOS, jamming, spoofing, etc) in AAM. These papers provide at least an introduction on cyberattacks in AAM. | O2: =D2 -> 134 | P2: =COUNTIFS(#REF!, "Y",#REF!, 1) -> #REF! | Q2: =O2-P2 -> #REF! | U2: =SUM(O2:O12) -> 224 | V2: =SUM(Q2:Q4) -> #REF!
A3: 2 | B3: Papers focused on Cyber-resilience & AAM: taxonomy of cyber-attacks, countermeasures, recommendations, safety and resilience perspective. | C3: =COUNTIF(Selected_papers!B:B,"2") -> 67 | D3: =COUNTIFS(Selected_papers!A:A, "Y",Selected_papers!B:B, 2) -> 60 | G3: Identification | H3: Screening | J3: Start Eligibility | M3: 2 | N3: Papers focused on Cyber-resilience & AAM: taxonomy of cyber-attacks, countermeasures, recommendations, safety and resilience perspective. | O3: =D3 -> 60 | P3: =COUNTIFS(#REF!, "Y",#REF!, 2) -> #REF! | Q3: =O3-P3 -> #REF!
A4: 3 | B4: Papers focused on Cyber-resilience & AAM: Literature review and surveys | C4: =COUNTIF(Selected_papers!B:B,"3") -> 30 | D4: =COUNTIFS(Selected_papers!A:A, "Y",Selected_papers!B:B, 3) -> 30 | J4: Total available | M4: 3 | N4: Papers focused on Cyber-resilience & AAM: Literature review and surveys | O4: =D4 -> 30 | P4: =COUNTIFS(#REF!, "Y",#REF!, 3) -> #REF! | Q4: =O4-P4 -> #REF!
A5: N0 | B5: Out of scope 0: technical publications that cover cybersecurity, communication, robust protocols, integrated network, blockchain, and other approaches to defending or addressing cyber-attacks in aviation or AAM. | C5: =COUNTIF(Selected_papers!B:B,"N0") -> 211 | D5: NA
A6: N1 | B6: Out of scope 1: papers on UAVs operations to monitoring, inspections, identification, assessment (industrial plants, agricolture, pipeline,wildlife,…) | C6: =COUNTIF(Selected_papers!B:B,"N1") -> 64 | D6: NA
A7: N2 | B7: Out of scope 2: papers focused on enhancing or adding new AAM/UAV features (Positioning through GPS, security, communication, flight mechanics, image acquisition, detection, antennas interference), other operational use. | C7: =COUNTIF(Selected_papers!B:B,"N2") -> 143 | D7: NA
A8: N3 | B8: Out of scope 3: papers on enhancing or adding new features applying neural network, AI, blockchain, machine learning algorithm, with little to none focus on cybersecurity, cyber-resilience, AAM, drones. | C8: =COUNTIF(Selected_papers!B:B,"N3") -> 20 | D8: NA
A9: N4 | B9: Out of scope 4: paper focused on different topic than AAM & Cybersecurity, completely out of scope | C9: =COUNTIF(Selected_papers!B:B,"N4") -> 18 | D9: NA
A10: D1 | B10: Discarded: type of document | C10: =COUNTIF(Selected_papers!B:B,"D1") -> 31 | D10: NA
A11: Duplicate | B11: Duplicates paper from the advanced search | D11: NA
C12: =SUM(C2:C11) -> 736 | D12: =SUM(D2:D4) -> 224

Sheet Scopus_Export
A1: Authors | B1: Author full names | C1: Author(s) ID | D1: Title | E1: Year | F1: Source title | G1: Volume | H1: Issue | I1: Art. No. | J1: Page start | K1: Page end | L1: Page count | M1: DOI | N1: Link | O1: Abstract | P1: Author Keywords | Q1: EID
A2: Novák A.; Kováčiková K.; Kandera B.; Sedláčková A.N. | B2: Novák, Andrej (9241050100); Kováčiková, Kristína (57226781703); Kandera, Branislav (57204831935); Sedláčková, Alena Novák (57842588600) | C2: 9241050100; 57226781703; 57204831935; 57842588600 | D2: Global Navigation Satellite Systems Signal Vulnerabilities in Unmanned Aerial Vehicle Operations: Impact of Affordable Software-Defined Radio | E2: 2024 | F2: Drones | G2: 8 | H2: 3 | I2: 109 | M2: 10.3390/drones8030109 | N2: https://www.scopus.com/inward/record.uri?eid=2-s2.0-85188723814&doi=10.3390%2fdrones8030109&partnerID=40&md5=736173188b2ac7aaf540895e18e677ad | O2: Spoofing, alongside jamming of the Global Navigation Satellite System signal, remains a significant hazard during general aviation or Unmanned Aerial Vehicle operations. As aircraft utilize various support systems for navigation, such as INS, an insufficient Global Navigation Satellite System signal renders Unmanned Aerial Vehicles nearly uncontrollable, thereby posing increased danger to operations within airspace and to individuals on the ground. This paper primarily focuses on assessing the impact of the budget friendly Software-Defined Radio, HackRF One 1.0, on the safety of Unmanned Aerial Vehicles operations. Considering the widespread use of Software-Defined Radio devices today, with some being reasonably inexpensive, understanding their influence on Unmanned Aerial Vehicles safety is crucial. The generation of artificial interference capable of posing a potential threat in expanding Unmanned Aerial Vehicles airspace is deemed unacceptable. © 2024 by the authors. | P2: GNSS; interference; jamming; UAV | Q2: 2-s2.0-85188723814
A3: Vélez S.; Ariza-Sentís M.; Panić M.; Ivošević B.; Stefanović D.; Kaivosoja J.; Valente J. | B3: Vélez, Sergio (57215185725); Ariza-Sentís, Mar (56964491300); Panić, Marko (33368184800); Ivošević, Bojana (56538600400); Stefanović, Dimitrije (58038387300); Kaivosoja, Jere (49861371000); Valente, João (42062501000) | C3: 57215185725; 56964491300; 33368184800; 56538600400; 58038387300; 49861371000; 42062501000 | D3: Speeding up UAV-based crop variability assessment through a data fusion approach using spatial interpolation for site-specific management | E3: 2024 | F3: Smart Agricultural Technology | G3: 8 | I3: 100488 | M3: 10.1016/j.atech.2024.100488 | N3: https://www.scopus.com/inward/record.uri?eid=2-s2.0-85196262805&doi=10.1016%2fj.atech.2024.100488&partnerID=40&md5=a1e1d2616c40f33c73617841adf84c71 | O3: Innovations in precision agriculture enhance complex tasks, reduce environmental impact, and increase food production and cost efficiency. One of the main challenges is ensuring rapid information availability for autonomous vehicles and standardizing processes across platforms to maximize interoperability. The lack of drone technology standardisation, communication barriers, high costs, and post-processing requirements sometimes hinder their widespread use in agriculture. This research introduces a standardized data fusion framework for creating real-time spatial variability maps using images from different Unmanned Aerial Vehicles (UAVs) for Site-Specific Crop Management (SSM). Two spatial interpolation methods were used (Inverse Distance Weight, IDW, and Triangulated Irregular Networks, TIN), selected for their computational efficiency and input flexibility. The proposed framework can use different UAV image sources and offers versatility, speed, and efficiency, consuming up to 98 % less time, energy, and computing requirements than standard photogrammetry techniques, providing rapid field information, allowing edge computing incorporation into the UAV data acquisition phase. Experiments conducted in Spain, Serbia, and Finland in 2022 under the H2020 FlexiGroBots project demonstrated a strong correlation between results from this method and those from standard photogrammetry techniques (up to r = 0.93). In addition, the correlation with Sentinel 2 satellite images was as strong as that obtained with photogrammetry-based orthomosaics (up to r = 0.8). The proposed approach could support irrigation leak detection, soil parameter estimation, weed management, and satellite integration for agriculture. © 2024 The Author(s) | P3: IDW; Precision agriculture; Remote sensing; Satellite; Spatial variability; TIN | Q3: 2-s2.0-85196262805
A4: Periyasami K.; Katina P.F.; Ramasamy R. | B4: Periyasami, Karthikeyan (59279792400); Katina, Polinpapilinho F. (39361629100); Ramasamy, Rajagopal (57254725400) | C4: 59279792400; 39361629100; 57254725400 | D4: Cyber Space and Outer Space Security | E4: 2024 | F4: Cyber Space and Outer Space Security | J4: 1 | K4: 266 | L4: 265 | N4: https://www.scopus.com/inward/record.uri?eid=2-s2.0-85201595905&partnerID=40&md5=2cf1d4dfc5c4c6f559fbff91c9e0c7be | O4: This book delves into cutting-edge research in cyberspace and outer space security, encompassing both theoretical and experimental aspects. It provides mitigation measures and strategies to address the identified challenges within. It covers a spectrum of topics including techniques and strategies for enhancing cyberspace security, combating ransomware attacks, and securing autonomous vehicles. Additionally, it explores security and surveillance systems involving autonomous vehicles, resilience schemes against security attacks using blockchain for autonomous vehicles, security analysis of autonomous drones (UAVs), the cybersecurity kill chain, the internet of drones (IoD), and cyberspace solutions to counteract attacks. The discussion extends to mitigation strategies against weaponized AI in cyber-attacks, countermeasures for both autonomous vehicles and cyberspace attacks, as well as the limitations and future prospects of artificial intelligence (AI) and data defense in aerospace cybersecurity. A network comprising nodes can establish both cyberspace and outer space platforms for data exchange. Cyberspace finds diverse applications, including commercial endeavors and military defense. The integration of autonomous vehicles, unmanned aircraft systems (UAS), and drones into outer space environments is facilitated through their connection to cyberspace. One illustrative example involves the utilization of blockchain-based secure drone systems for product delivery, leveraging the combined capabilities of cyberspace and outer space security technologies. This book elucidates the intricate dynamics between cyber operations and the expanding realm of autonomous outer cyberspace, presenting new security challenges arising from heightened complexity and emerging vulnerabilities. © 2024 River Publishers. All rights reserved. | Q4: 2-s2.0-85201595905
A5: Guo D.; Tang L.; Zhang X.; Liang Y.-C. | B5: Guo, Delin (57215897646); Tang, Lan (35504073000); Zhang, Xinggan (7410277485); Liang, Ying-Chang (36071330300) | C5: 57215897646; 35504073000; 7410277485; 36071330300 | D5: Joint Optimization of Trajectory and Jamming Power for Multiple UAV-Aided Proactive Eavesdropping | E5: 2024 | F5: IEEE Transactions on Mobile Computing | G5: 23 | H5: 5 | I5: 10238835 | J5: 5770 | K5: 5785 | L5: 15 | M5: 10.1109/TMC.2023.3311484 | N5: https://www.scopus.com/inward/record.uri?eid=2-s2.0-85171565918&doi=10.1109%2fTMC.2023.3311484&partnerID=40&md5=9dc452d4a3e8dc2ea012068292ac3409 | O5: This paper studies a novel wireless information surveillance scenario, where the legitimate party aims to eavesdrop on multiple suspicious communication links with the help of multiple unmanned aerial vehicles (UAVs). Each suspicious link is comprised of a UAV (transmitter) and its fixed destination. To improve the eavesdropping ability, cooperative legitimate UAVs emit jamming signals to reduce the capacities of suspicious channels and plan the flight trajectory to enhance the capacity of the eavesdropping channels. Considering the system dynamics, it is natural to model this sequential decision-making problem as a Markov Decision Process (MDP), which might be solved by reinforcement learning (RL). However, it is difficult to design a policy in RL that determines jamming powers satisfying the considered eavesdropping constraints. Therefore, we decompose the optimization process into two phases, 1) obtaining the non-learning-based optimal solver for jamming power allocation under each state, and 2) optimizing the policy of moving action by RL. We will show this decoupled optimization process also holds the optimality. Considering the flying safety, we will determine the individual moving policy for each legitimate UAV rather than a centralized policy that controls all UAVs. Finally, extensive simulations are conducted to demonstrate the effectiveness of the proposed solution. © 2023 IEEE. | P5: power allocation; Proactive eavesdropping; reinforcement learning (RL); trajectory planning; unmanned aerial vehicles (UAVs) | Q5: 2-s2.0-85171565918
A6: Hu M.; Yan X.; Qiu M.; Zhang P.; Wang S. | B6: Hu, Manman (59144293500); Yan, Xiao (58000704500); Qiu, Mingjie (58599992300); Zhang, Peng (58787459400); Wang, Shengli (54992019700) | C6: 59144293500; 58000704500; 58599992300; 58787459400; 54992019700 | D6: Interference Resource Allocation Method Based on Constrained Reinforcement Learning | E6: 2024 | F6: Proceedings of SPIE - The International Society for Optical Engineering | G6: 13283 | I6: 1328340 | M6: 10.1117/12.3037194 | N6: https://www.scopus.com/inward/record.uri?eid=2-s2.0-85212823571&doi=10.1117%2f12.3037194&partnerID=40&md5=c1ff7e4f34130e8989d86f0ee9f5d90e | O6: In modern manned-unmanned cooperative flight formations confronting advanced ground-based radar networks, traditional UAV swarm jamming strategies rely heavily on centralized command from fixed nodes. This centralization, while optimizing decision quality through global situational awareness, also introduces significant vulnerabilities. Dependence on a single node makes the system prone to failure in high-intensity and uncertain environments. Additionally, UAV platform constraints, such as limited power, sensing range, and communication bandwidth, challenge the feasibility of centralized information processing across the entire network. To address these issues, this study presents a decentralized decision-making framework, incorporating an adaptive cluster jamming resource allocation strategy based on collaborative multi-agent reinforcement learning. The Actor-Critic (AC) algorithm is employed to enable autonomous behavior analysis of UAV swarms via policy networks, while a value network is utilized to evaluate and guide policy iterations. The simulation results showed an interference mode allocation result of 20 drones interfering with 3 radars, verifying the possibility of this strategy working in complex dynamic environments. © 2024 SPIE. | P6: Distributed Decision-Making Framework; Multi-Agent Reinforcement Learning; Unmanned Aerial Vehicles (UAVs) | Q6: 2-s2.0-85212823571
A7: Alharthi R. | B7: Alharthi, Raed (57203659754) | C7: 57203659754 | D7: Enhancing unmanned aerial vehicle and smart grid communication security using a ConvLSTM model for intrusion detection | E7: 2024 | F7: Frontiers in Energy Research | G7: 12 | I7: 1491332 | M7: 10.3389/fenrg.2024.1491332 | N7: https://www.scopus.com/inward/record.uri?eid=2-s2.0-85212753771&doi=10.3389%2ffenrg.2024.1491332&partnerID=40&md5=b6ba95c0928536816d94e84406a7688e | O7: The emergence of small-drone technology has revolutionized the way we use drones. Small drones leverage the Internet of Things (IoT) to deliver location-based navigation services, making them versatile tools for various applications. Unmanned aerial vehicle (UAV) communication networks and smart grid communication protocols share several similarities, particularly in terms of their architecture, the nature of the data they handle, and the security challenges they face. To ensure the safe, secure, and reliable operation of both, it is imperative to establish a secure and dependable network infrastructure and to develop and implement robust security and privacy mechanisms tailored to the specific needs of this domain. The research evaluates the performance of deep learning models, including convolutional neural networks (CNN), long short-term memory (LSTM), CNN-LSTM, and convolutional long short-term memory (ConvLSTM), in detecting intrusions within UAV communication networks. The study utilizes five diverse and realistic datasets, namely, KDD Cup-99, NSL-KDD, WSN-DS, CICIDS 2017, and Drone, to simulate real-world intrusion scenarios. Notably, the ConvLSTM model consistently achieves an accuracy of 99.99%, showcasing its potential in securing UAVs from cyber threats. By demonstrating its superior performance, this work highlights the importance of tailored security mechanisms in safeguarding UAV technology against evolving cyber threats. Ultimately, this research contributes to the growing body of knowledge on UAV security, emphasizing the necessity of high-quality datasets and advanced models in ensuring the safe, secure, and reliable operation of UAV systems across various industries. Copyright © 2024 Alharthi. | P7: communication security; cyber resilience; intrusion detection; smart grid; unmanned aerial vehicles | Q7: 2-s2.0-85212753771
A8: Basak S.; Rajendran S.; Pollin S.; Scheers B. | B8: Basak, Sanjoy (57191051079); Rajendran, Sreeraj (57191669277); Pollin, Sofie (8601601500); Scheers, Bart (23478501400) | C8: 57191051079; 57191669277; 8601601500; 23478501400 | D8: Spectrum Prediction for Protocol-Aware RF Jamming | E8: 2024 | F8: IEEE Transactions on Cognitive Communications and Networking | G8: 10 | H8: 2 | J8: 363 | K8: 373 | L8: 10 | M8: 10.1109/TCCN.2023.3327538 | N8: https://www.scopus.com/inward/record.uri?eid=2-s2.0-85176301898&doi=10.1109%2fTCCN.2023.3327538&partnerID=40&md5=7fa595e799408171cafd4d9ba0cf5e40 | O8: Neutralizing a drone using a protocol-aware RF jammer requires precise knowledge of the occupied spectrum in the time and frequency domains. This paper aims to develop an automatic spectrum prediction framework utilizing the Convolutional Neural Network (CNN) and Long Short Term Memory (LSTM) models. We generate a synthetic dataset using the commonly used drone signal properties and parameters, and evaluate the prediction performance under several realistic scenarios. Our experiment shows that the CNN-LSTM model can accurately predict future time and frequency sequences by using the spectrogram matrix as the input. We obtained better prediction performance with lower computational costs with our framework compared to the existing frameworks. Furthermore, we show that the CNN-LSTM model can predict future time-frequency sequences of unseen hopping rates and patterns when using transfer learning. The performance validation is also performed using real drone RF signals. Furthermore, we present a two-stage spectrum prediction approach that achieves excellent performance by offering higher frequency resolutions while maintaining a lower computational cost. © 2015 IEEE. | P8: Deep learning; spectrum prediction; UAVs | Q8: 2-s2.0-85176301898
A9: Kumar N.; Chaudhary A. | B9: Kumar, Naveen (59253135800); Chaudhary, Ankit (36600087600) | C9: 59253135800; 36600087600 | D9: Surveying cybersecurity vulnerabilities and countermeasures for enhancing UAV security | E9: 2024 | F9: Computer Networks | G9: 252 | I9: 110695 | M9: 10.1016/j.comnet.2024.110695 | N9: https://www.scopus.com/inward/record.uri?eid=2-s2.0-85200806532&doi=10.1016%2fj.comnet.2024.110695&partnerID=40&md5=b9ac0c4a03c15f1d66aefbbd47166ef1 | O9: Drones and other forms of Unmanned Aerial Vehicles (UAVs) usages are increasing with time from military operations like surveillance, reconnaissance to commercial operations such as transportation, agriculture. The Drone market will be grown to around 43 billion USD by the 2025. With the increase in the usages, there is increase in cyber-attacks. So, Drone security and privacy are of major concern as they are used to perform the critical operations. The rapid adoption of UAVs in various sectors has prompted the need for robust and comprehensive cyber security measures. By implementing robust countermeasures, such as authentication, encryption etc. the risks posed by cyber threats can be significantly mitigated. The study investigates cyber security vulnerabilities and countermeasures in UAV systems within the scope of Authentication techniques, Physical Layer Security, Covert Communication. Relaying and Trajectory Optimization techniques are also discussed so that the flight trajectory can be optimized. It also discusses the communication modes used in UAV communication. An analysis of communication protocols is also carried out in this survey. The goal of the survey is to get the idea of cyber security threats involved in UAV communication. Our analysis emphasizes the importance of a holistic approach to UAV cyber security, leveraging the synergies among these domains to enhance overall resilience. © 2024 Elsevier B.V. | P9: Authentication; Covert communication; Cryptography; Cyber-attacks; GCS; Physical layer security; Relaying; Trajectory optimization; UAV | Q9: 2-s2.0-85200806532
A10: Liu Z.; Zhu B.; Xie Y.; Ma K.; Guan X. | B10: Liu, Zhixin (55714815900); Zhu, Ben (58796416200); Xie, Yuanai (57325394200); Ma, Kai (36650969700); Guan, Xinping (57392292000) | C10: 55714815900; 58796416200; 57325394200; 36650969700; 57392292000 | D10: UAV-Aided Secure Communication With Imperfect Eavesdropper Location: Robust Design for Jamming Power and Trajectory | E10: 2024 | F10: IEEE Transactions on Vehicular Technology | G10: 73 | H10: 5 | J10: 7276 | K10: 7286 | L10: 10 | M10: 10.1109/TVT.2023.3347769 | N10: https://www.scopus.com/inward/record.uri?eid=2-s2.0-85181572608&doi=10.1109%2fTVT.2023.3347769&partnerID=40&md5=0ffc3036a4f824d4629aa556876b17a5 | O10: This paper exploits the mobility of an unmanned aerial vehicle (UAV) to improve the physical layer (PLS) security against potential eavesdropping scenarios, where the sensitive data transmitted from a ground base station (GBS) to multiple information receivers (IRs) is easily eavesdropped by multiple non-colluding eavesdroppers (Eves). Specifically, the UAV is employed as a friendly jammer to transmit artificial noise to degrade the wiretap channels. By leveraging the UAV's mobility and the possibility of establishing line-of-sight links, the UAV can move close to the Eves and opportunistically jam them. Especially, two practical factors, namely, the imperfect location information of Eves and the existence of no-fly zones are considered. Since only the partial position information of the Eves can be known, as the worst case, the minimum average secrecy rate of IRs is robustly optimized by jointly designing the trajectory and jamming power of the UAV, and the transmission power of the GBS to ensure the security of all IRs. However, the formulated problem with coupled variables is non-convex and intractable. As such, an efficient alternative iterative suboptimal algorithm is proposed to solve this problem by applying the block coordinate descent, successive convex approximation, slack variables, and mathcal {S}-Procedure. Numerical results reveal that the proposed robust algorithm can substantially improve the max-min average secrecy rate, and the effectiveness of the proposed algorithm is further verified by comparing it with three benchmark schemes. © 1967-2012 IEEE. | P10: no-fly-zone; physical layer security; robust design; trajectory optimization; transmit power optimization; UAV-adied communication | Q10: 2-s2.0-85181572608
A11: Gupta S.K.; Kumar M.; Nayyar A.; Mahajan S. | B11: Gupta, Sachin Kumar (57213337960); Kumar, Manoj (59315839100); Nayyar, Anand (55201442200); Mahajan, Shubham (57209224750) | C11: 57213337960; 59315839100; 55201442200; 57209224750 | D11: Unmanned Aircraft Systems | E11: 2024 | F11: Unmanned Aircraft Systems | J11: 1 | K11: 653 | L11: 652 | M11: 10.1002/9781394230648 | N11: https://www.scopus.com/inward/record.uri?eid=2-s2.0-85213776471&doi=10.1002%2f9781394230648&partnerID=40&md5=7d85f7ff56c8353d7c530259fa997e81 | O11: This book is an essential resource for anyone looking to understand the cutting-edge applications and evolving technologies of Unmanned Aerial Systems, showcasing how they enhance safety and efficiency in monitoring, emergency response, and smart city development. With the evolution of Unmanned Aircraft Systems (UAS), its applications can be observed in the fields of monitoring for fire detection, sustainable computing, emergencies, and law enforcement. They can be useful for monitoring or screening applications, as well as the deployment of smart cities, security monitoring, and communication establishments at rare locations or unapproachable locations. Thus, the wireless ad-hoc networks of Unmanned Aerial Vehicles (UAVs) and infrastructure-based UAVs can be utilized in this proposal. Unmanned aircraft systems (UAS) extend human potential and allow us to execute dangerous or difficult tasks safely and efficiently, saving time, money, and, most importantly, lives. UAS can help police, fire, and other public workers save lives in emergencies like natural disasters, locate missing animals and children, or help fight fighters. Unmanned Aircraft Systems contains novel contributions and emerging trends in the area of Unmanned Aerial Vehicles (UAV), drones, and aircraft without a human pilot aboard. It has three segments incorporating technological advancements and future trends in UAS, the policies and security aspects of UAVs, and their applications as an intelligent system. Along with these state-of-the-art techniques, this book also incorporates advances in AI and machine learning, deep learning, IoT technology, cybersecurity and Blockchain, UAV regulation policies in the United States and Europe, SOTA in ITS, and many more technological advancements, which makes this book the pioneer and benchmarking reference in these areas. © 2025 Scrivener Publishing LLC. | Q11: 2-s2.0-85213776471
A12: Lu F.; Liu G.; Lu W.; Gao Y.; Cao J.; Zhao N.; Nallanathan A. | B12: Lu, Fangwei (57216841914); Liu, Gongliang (15065645300); Lu, Weidang (59454513400); Gao, Yuan (57113859700); Cao, Jiang (57215003444); Zhao, Nan (45562028800); Nallanathan, Arumugam (6603561059) | C12: 57216841914; 15065645300; 59454513400; 57113859700; 57215003444; 45562028800; 6603561059 | D12: Resource and Trajectory Optimization for UAV-Relay-Assisted Secure Maritime MEC | E12: 2024 | F12: IEEE Transactions on Communications | G12: 72 | H12: 3 | J12: 1641 | K12: 1652 | L12: 11 | M12: 10.1109/TCOMM.2023.3330884 | N12: https://www.scopus.com/inward/record.uri?eid=2-s2.0-85177032462&doi=10.1109%2fTCOMM.2023.3330884&partnerID=40&md5=6f90332308c96404c39e8780bf774c73 | O12: With the evolutional development of maritime networks, the explosive growth of maritime data has put forward elevated demands for the computing capabilities of maritime devices (MDs). Unmanned aerial vehicle (UAV) is able to alleviate the computing pressure of MDs by forwarding the computing tasks to the edge server on the coast. However, UAV relaying introduces a significant security challenge due to the vulnerability of line-of-sight (LoS) communication channels, which can be exploited for eavesdropping on computing tasks. In this paper, an efficient secure communication scheme is proposed for UAV-relay-assisted maritime mobile edge computing (MEC) with a flying eavesdropper. The secure computing capacity of MDs is maximized by jointly optimizing the transmit power, time slot allocation factor, computation optimization and UAV trajectory. Due to multi-variable coupling, the formulated optimization problem (OP) is non-convex. We first transform OP by introducing auxiliary variables. Then, the transformed OP is decomposed and solved in an iterative manner by applying block coordinate descent (BCD) and successive convex approximation (SCA). Numerical results show that the secure computing capability of the UAV-relay-assisted maritime MEC system of proposed secure communication scheme can be effectively improved compared with benchmarks. © 1972-2012 IEEE. | P12: maritime communications; MEC; Secure transmission; UAV-relay | Q12: 2-s2.0-85177032462
A13: Choi S.; Lee J.; Park B.; Jo J. | B13: Choi, Seungho (56889987900); Lee, Junghoon (56545183700); Park, Byungkoo (16639040400); Jo, Jeil (57202046191) | C13: 56889987900; 56545183700; 16639040400; 57202046191 | D13: Implementation and Validation of a Real-time Spoofing System | E13: 2024 | F13: 2024 21st European Radar Conference, EuRAD 2024 | J13: 252 | K13: 255 | L13: 3 | M13: 10.23919/EuRAD61604.2024.10734883 | N13: https://www.scopus.com/inward/record.uri?eid=2-s2.0-85210863711&doi=10.23919%2fEuRAD61604.2024.10734883&partnerID=40&md5=599a5368e2cdaa9dde477a71c8cf6cc8 | O13: Satellite navigation deception, also known as spoof jamming technology, is crucial as an anti-drone technology being developed alongside the revitalization of the drone industry. Unlike existing simulator-type or non-real-time signal generators, this advanced drone jamming technology combines a spoofing deception signal generator with real-time target information and navigation satellite orbit data. In this study, we outlined the design, manufacturing results, and core real time performance metrics, including time and navigation message synchronization. To validate the possibility of directional guidance of an autonomous UAV through spoofing techniques, we developed a novel deception procedure and successfully demonstrated its effectiveness in controlling the flight direction of an autonomous UAV through spoof jamming. © 2024 European Microwave Association (EuMA). | P13: anti-drone; counter-measuring UAV; GNSS spoofing | Q13: 2-s2.0-85210863711
A14: Belfadel D.; Haessig D. | B14: Belfadel, Djedjiga (55915134800); Haessig, David (59389740600) | C14: 55915134800; 59389740600 | D14: Optical Flow for Drone Horizontal Velocity Estimation without GPS | E14: 2024 | F14: FUSION 2024 - 27th International Conference on Information Fusion | M14: 10.23919/FUSION59988.2024.10706252 | N14: https://www.scopus.com/inward/record.uri?eid=2-s2.0-85207692634&doi=10.23919%2fFUSION59988.2024.10706252&partnerID=40&md5=d4382b7bec95ffe88fdcfcbfcc42307b | O14: Unmanned aerial vehicles (UAVs) are widely used in military and civilian applications, such as surveillance, disaster monitoring, and rescue missions. They rely heavily on global positioning systems (GPS) for navigation. However, the accuracy and availability of GPS positioning, navigation, and timing (PNT) data can suffer losses due to jamming and spoofing. To address overreliance on GPS infrastructure, this paper presents a vision-aided system to enable UAVs to estimate velocity and continue operation when GPS signal is intermittently lost. The system fuses data from onboard sensors including the inertial measurement unit (IMU), barometer, and optical flow camera using an extended Kalman filter (EKF). The efficiency of this approach was validated through simulation experiments involving a UAV navigating in a circular and square motions. Statistical analysis confirmed the proposed system can provide state estimation and smooth trajectory control for UAVs during GPS signal outages. © 2024 ISIF. | P14: IMU; Navigation; Optical Flow; UAVs | Q14: 2-s2.0-85207692634
A15: Zahid M.U.; Nisar M.D.; Fazil A.; Ryu J.; Shah M.H. | B15: Zahid, Muhammad Usama (57965916300); Nisar, Muhammad Danish (17435054000); Fazil, Adnan (56121926300); Ryu, Jihyoung (36519735000); Shah, Maqsood Hussain (57206854889) | C15: 57965916300; 17435054000; 56121926300; 36519735000; 57206854889 | D15: Composite Ensemble Learning Framework for Passive Drone Radio Frequency Fingerprinting in Sixth-Generation Networks | E15: 2024 | F15: Sensors | G15: 24 | H15: 17 | I15: 5618 | M15: 10.3390/s24175618 | N15: https://www.scopus.com/inward/record.uri?eid=2-s2.0-85203871690&doi=10.3390%2fs24175618&partnerID=40&md5=2433f2c778c82a41d55170afbe1d6537 | O15: The rapid evolution of drone technology has introduced unprecedented challenges in security, particularly concerning the threat of unconventional drone and swarm attacks. In order to deal with threats, drones need to be classified by intercepting their Radio Frequency (RF) signals. With the arrival of Sixth Generation (6G) networks, it is required to develop sophisticated methods to properly categorize drone signals in order to achieve optimal resource sharing, high-security levels, and mobility management. However, deep ensemble learning has not been investigated properly in the case of 6G. It is anticipated that it will incorporate drone-based BTS and cellular networks that, in one way or another, may be subjected to jamming, intentional interferences, or other dangers from unauthorized UAVs. Thus, this study is conducted based on Radio Frequency Fingerprinting (RFF) of drones identified to detect unauthorized ones so that proper actions can be taken to protect the network’s security and integrity. This paper proposes a novel method—a Composite Ensemble Learning (CEL)-based neural network—for drone signal classification. The proposed method integrates wavelet-based denoising and combines automatic and manual feature extraction techniques to foster feature diversity, robustness, and performance enhancement. Through extensive experiments conducted on open-source benchmark datasets of drones, our approach demonstrates superior classification accuracies compared to recent benchmark deep learning techniques across various Signal-to-Noise Ratios (SNRs). This novel approach holds promise for enhancing communication efficiency, security, and safety in 6G networks amidst the proliferation of drone-based applications. © 2024 by the authors. | P15: deep ensemble learning; deep learning; drone fingerprint; ensemble learning; RF fingerprinting; specific emitter identification | Q15: 2-s2.0-85203871690
A16: Liaquat S.; Faizan M.; Chattha J.N.; Butt F.A.; Mahyuddin N.M.; Naqvi I.H. | B16: Liaquat, Salman (58725072100); Faizan, Muhammad (57195627743); Chattha, Jawwad Nasar (26029321500); Butt, Faran Awais (55825797000); Mahyuddin, Nor Muzlifah (24448238900); Naqvi, Ijaz Haider (23009130600) | C16: 58725072100; 57195627743; 26029321500; 55825797000; 24448238900; 23009130600 | D16: A framework for preventing unauthorized drone intrusions through radar detection and GPS spoofing | E16: 2024 | F16: Ain Shams Engineering Journal | G16: 15 | H16: 5 | I16: 102707 | M16: 10.1016/j.asej.2024.102707 | N16: https://www.scopus.com/inward/record.uri?eid=2-s2.0-85186886308&doi=10.1016%2fj.asej.2024.102707&partnerID=40&md5=1558b9002875c0b5d44d3ec9f070785d | O16: The increasing use of Global Positioning System (GPS)-based autonomous drones in various civilian and military applications has raised concerns about malicious or unintentionally harmful activities that can be carried through them. It is necessary to detect these intruding drones within protected areas and prevent their unauthorized access by denying them entry. We propose a framework that combines the detection of intruding drones using an L-band radar and then counters by transmitting fake GPS coordinates toward the drones, effectively redirecting them. This article explains the setup required to add to an existing monostatic radar that provides two-dimensional information, i.e., range and azimuth information, to enable the proposed setup to get the elevation angle of the drone. We propose a linear array design using digital receive-only beamforming techniques in the elevation domain to compute the elevation angle in addition to the range, velocity, and azimuth information being provided by the monostatic radar to get complete information about the intruding drone. The simulation of drone detection is followed by an examination of the impact of transmitting fabricated GPS coordinates to the drone. Experimental verification has been conducted to validate both the digital beamforming algorithm and the spoofing technique. This approach blocks the reception of actual GPS signals in the drone and replaces the drone's GPS coordinates with alternative, desired coordinates. The proposed framework can be used to prevent unauthorized drone intrusions in the protected area. © 2024 The Author(s) | P16: Digital beamforming; Drones; Global Positioning System (GPS); Pulse-Doppler radar; Software-Defined Radios (SDRs); Spoofing; Unmanned Aerial Vehicles (UAVs) | Q16: 2-s2.0-85186886308
A17: Thangam S.; Gupta P.K.; Kartthikeyan N.; Mukil L.D.; Niranjan D.K. | B17: Thangam, S. (35173605500); Gupta, Pradeep Kumar (59421081700); Kartthikeyan, N. (59420934200); Mukil, L.D. (59420022400); Niranjan, D.K. (57219282984) | C17: 35173605500; 59421081700; 59420934200; 59420022400; 57219282984 | D17: Low-Cost Network Jammer for Wi-Fi Network in Civilian Areas | E17: 2024 | F17: Proceedings of the 5th International Conference on Smart Electronics and Communication, ICOSEC 2024 | J17: 666 | K17: 672 | L17: 6 | M17: 10.1109/ICOSEC61587.2024.10722738 | N17: https://www.scopus.com/inward/record.uri?eid=2-s2.0-85209943378&doi=10.1109%2fICOSEC61587.2024.10722738&partnerID=40&md5=8e29ddee59542601e00e8cafbb626128 | O17: This application presents a novel approach to address the challenge of intercepting unmanned aerial vehicles (UAVs) operating within the 2.4 GHz frequency band. Jamming device operating at 2.4 GHz, with an Arduino Nano microcontroller and nRF24L01 module included. The device is designed to accurately search available wireless networks in a specific frequency range, focused on intercepting connections between drones in this spectrum Real-time system identifies networks and selects the channels, thus disconnecting targeted frequency devices Security measures in the presence of counter-drone activities are required This technology is an important tool for growth. Using Arduino Nano and nRF24L01 modules, the jamming device offers a flexible and scalable solution designed for network security professionals. The 2.4 GHz jammer provides precise interference, allowing targeted disruption of drones operating in a specific frequency band. In addition, the paper provides a detailed introduction to well-known drones operating in the 2.4 GHz frequency range, such as the DJI Phantom series and the Parrot Bebop series, and understanding these drones is crucial for planning effective countermeasures. The paper includes implementation data and results of experimental tests, providing insights into the efficiency and feasibility of a 2.4 GHz jammer designed to combat interference in UAV networks in a specific frequency band to be used. © 2024 IEEE. | P17: 2.4 GHz; Network disturbance; Security; Wi-Fi disturbance | Q17: 2-s2.0-85209943378
A18: Petro P.; Bauer P. | B18: Petro, Peter (59309498100); Bauer, Peter (57220722317) | C18: 59309498100; 57220722317 | D18: Mono camera-based GPS spoofing detection for aerial vehicles | E18: 2024 | F18: IFAC-PapersOnLine | G18: 58 | H18: 4 | J18: 126 | K18: 131 | L18: 5 | M18: 10.1016/j.ifacol.2024.07.205 | N18: https://www.scopus.com/inward/record.uri?eid=2-s2.0-85202902745&doi=10.1016%2fj.ifacol.2024.07.205&partnerID=40&md5=88153416f1521eefad3021579044342d | O18: This paper presents mono camera-based GPS spoofing detection for aerial vehicles utilizing only image information besides the initial orientation of the vehicle. Orientation information is propagated and motion direction is estimated solely from the mono camera images through the estimation of the essential matrix. Histograms of Oriented Displacements and their correlation are considered to detect spoofing considering GPS and image-based data. Straight and turning simulated fight trajectories of a fixed wing research drone with different turbulence levels are compared to evaluate the method. The results are promising with timely detection of every spoofing scenario and without false alarm. The exploration of real fight data is the topic of future development. © 2024 The Authors. This is an open access article under the CC BY-NC-ND license. | P18: GPS spoofing detection; mono camera relative motion; UAV | Q18: 2-s2.0-85202902745
A19: Alquwayzani A.A.; Albuali A.A. | B19: Alquwayzani, Alanoud A. (58297749000); Albuali, Abdullah A. (57196185950) | C19: 58297749000; 57196185950 | D19: A Systematic Literature Review of Zero Trust Architecture for Military UAV Security Systems | E19: 2024 | F19: IEEE Access | G19: 12 | J19: 176033 | K19: 176056 | L19: 23 | M19: 10.1109/ACCESS.2024.3503587 | N19: https://www.scopus.com/inward/record.uri?eid=2-s2.0-85210298511&doi=10.1109%2fACCESS.2024.3503587&partnerID=40&md5=adb708bc137d1c71da1901c726cafeb7 | O19: Over the last couple of years, the application of autonomous systems such as drones has been widely accepted, and these applications are used in the defense, safety, logistics, delivery, and consumer sectors. Unmanned Aerial Vehicles (UAVs) play a major role in contemporary battles by collecting intelligence, surveillance, reconnaissance, and aiding tactical procedures. Although the intricate interlinking of these systems and the high rate of cyber risk pose security challenges, there are ways to overcome them. Traditional security approaches based on border patrols and protective measures are unreliable against advanced and persistent threats. As a result, the Zero Trust (ZT) approach, which operates under the notion that no faith can be taken for granted in the network, is certainly the most appropriate way to deal with this issue. The main purpose of zero trust in UAV security is to reduce the vulnerability of the system to cyber threats. The core of zero trust is based on observing all activities and risks. This approach will help military UAV operators allow only genuine users to access UAV systems, thereby reducing the possibility of illegal access, hacking, and data breaches. This project aims to analyze the applicability of a zero-trust architecture model and machine learning to enhance the security of military drones. This study conducted a systematic review aimed at identifying different aspects of cybersecurity strategies for protecting UAV systems. Furthermore, a zero-trust architecture is presented in this study as an effective prospective solution to the security issues. © 2013 IEEE. | P19: cybersecurity; drone; Internet of Battlefield Things (IoBT); military UAVs; Security; suspicious behavior; UAV; UAV security; zero trust architecture (ZTA) | Q19: 2-s2.0-85210298511
A20: Sabuwala N.A.; Daruwala R.D. | B20: Sabuwala, Noshin A. (58122117800); Daruwala, Rohin D. (35795271200) | C20: 58122117800; 35795271200 | D20: An approach to enhance the security of unmanned aerial vehicles (UAVs) | E20: 2024 | F20: Journal of Supercomputing | G20: 80 | H20: 7 | J20: 9609 | K20: 9639 | L20: 30 | M20: 10.1007/s11227-023-05811-1 | N20: https://www.scopus.com/inward/record.uri?eid=2-s2.0-85179310352&doi=10.1007%2fs11227-023-05811-1&partnerID=40&md5=f1a96cb99d846bae7139d6fb6a47ff5d | O20: There is a significant surge in unmanned aerial vehicles’ (UAVs) popularity with an ongoing increase in demand due to their multi-functional uses. The capacity of the UAVs to respond to society and industry needs account for their pervasiveness. UAVs can be strategically deployed to enhance network efficiency and support critical missions, including vital tasks like infrastructure monitoring operations. To be effective, a UAV must interact securely with its network’s entities, such as ground control stations, other UAVs, air traffic control systems, and navigation satellite systems. UAVs are exposed to a dangerous and costly world of cyber dangers as a result of cyber technology and connections. The UAV and the Ground Control Station (GCS) exchange information using communication lines, which are vulnerable to cyber-attacks. As a result, detective, defensive, and preventative countermeasures are critical. The Micro Air Vehicle Link (MAVLink) protocol is a widely used lightweight communication protocol for enabling communication between UAVs and GCSs. It outlines communication exchanges between a GCS and a UAV. It carries information about the UAV’s condition as well as commands for control from the GCS. Although widely used, the MAVLink protocol lacks sufficient security measures and is susceptible to various types of attacks, which can pose significant risks to public safety. UAV data should be encrypted because they are very sensitive. To give a high level of security, complex operation encryption techniques are developed. These mathematical operations bring forth issues with efficiency and power usage, though. One of these methods, the ChaCha cipher, recently gained popularity after Google used it in several applications. In the current study, a new stream cipher method with low-duty cycles is proposed for protecting data in UAVs and is compared with existing security algorithms on the basis of various factors. The research findings show that by including the suggested method in MAVLink, it is possible to maintain both message secrecy and battery life for a resource-constrained UAV. This can be done while using comparable amounts of memory and CPU and without affecting MAVLink’s performance. © The Author(s), under exclusive licence to Springer Science+Business Media, LLC, part of Springer Nature 2023. | P20: Communication security; Internet of things (IoT); MAVLink; Stream cipher; Unmanned aerial vehicles (UAVs) | Q20: 2-s2.0-85179310352
A21: Anghuwo J.S.; Imanuel P.; Nangolo S.S. | B21: Anghuwo, John Shivute (59129871600); Imanuel, Peter (59129684000); Nangolo, Sam Shimakeleni (59128922100) | C21: 59129871600; 59129684000; 59128922100 | D21: Anti-unmanned aerial vehicle detection system for airports: aviation and national security perspective | E21: 2024 | F21: Journal of Transportation Security | G21: 17 | H21: 1 | I21: 12 | M21: 10.1007/s12198-024-00280-w | N21: https://www.scopus.com/inward/record.uri?eid=2-s2.0-85193254114&doi=10.1007%2fs12198-024-00280-w&partnerID=40&md5=760c51441934acfdeefd202f86a6ca51 | O21: Unmanned Aerial Vehicles gained significant popularity in the last decade as demonstrated by their wide usage in various fields. From around the year 2001, the usage of unmanned aerial vehicles’ technology was mainly confined to law enforcement agencies such as the military, police, and customs. In the contemporary, terrorists have also been observed to be using unmanned aerial vehicles to attack aviation facilities. The current paper examines the levels of vulnerability of the Namibian airports to possible intrusion and attack from unmanned aerial vehicles, a situation that could pose a serious threat to aviation and national security. Adopting a qualitative research approach, the study made use of a questionnaire and semi-structured interview guide to collect primary data from the participants. Microsoft Excel was used to analyse the data. The study establishes that Namibian airports are prone to attacks from unmanned aerial vehicles as there are no anti-unmanned aerial vehicle detection systems installed at all airports in the country. Thus, there is clear evidence that the Namibia Civil Aviation Authority and the Namibian Airport Company’s regulations and policies on aviation safety and security did not prioritise the installation of anti-unmanned aerial vehicle detection systems at all airports in Namibia. The paper suggests that, in order to enhance aviation safety and security, a joint civil/military Information Technology Unit, responsible for spoofing, detection, and the monitoring of illicit unmanned aerial vehicle operations should be set up and operations activated at all airports and other public infrastructures in Namibia. © The Author(s) 2024. | P21: Airports’ vulnerability; Anti-unmanned aerial vehicle detection system; Aviation safety and security; National security; UAV attack; UAVs | Q21: 2-s2.0-85193254114
A22: Alzahrani M.Y. | B22: Alzahrani, Mohammed Y. (56125509600) | C22: 56125509600 | D22: Enhancing Drone Security Through Multi-Sensor Anomaly Detection and Machine Learning | E22: 2024 | F22: SN Computer Science | G22: 5 | H22: 5 | I22: 651 | M22: 10.1007/s42979-024-02983-2 | N22: https://www.scopus.com/inward/record.uri?eid=2-s2.0-85195944082&doi=10.1007%2fs42979-024-02983-2&partnerID=40&md5=6200a876d8badd2677146c02a2082dfb | O22: Unmanned Aerial Vehicles (UAVs), commonly referred to as drones, have determined numerous applications across industries, ranging from aerial surveillance to package shipping. As drones are used in vital operations, ensuring cyberattacks and anomalies protect them from attackers is now a big challenge. This research study presents a complete approach to enhancing drone safety by integrating multi-sensor anomaly detection and superior machine learning techniques. The proposed methodology capitalizes on the rich sensor suite embedded in present-day drones, encompassing GPS receivers, accelerometers, gyroscopes, cameras, communication modules, and more. Leveraging an array of sensors in drones, our technique detects abnormal drone behavior indicative of unauthorized access, GPS spoofing, communication jamming, and malicious activities. By extracting features from sensor records, we develop a robust anomaly detection framework using the “uav attack dataset” able to identify deviations from normal flight patterns, communication signals, and environmental interactions. Central to our methodology is the utilization of machine learning algorithms. These algorithms are skilled on labeled datasets containing numerous flight eventualities, each normal and hostile, together with the ones discovered inside the “uav attack dataset”. The obtained results are eventually evaluated using rigorous performance metrics to quantify their effectiveness in distinguishing genuine anomalies from benign variations. The findings of our study underscore the capacity of multi-sensor anomaly detection for drones. By harnessing the power of machine learning and sensor fusion, we exhibit the ability to hit upon attacks at an early level, mitigating capability harm and permitting rapid responses. This study contributes now not only to the field of drone safety but also to the broader panorama of self-sustaining systems protection, highlighting the importance of adaptive and proactive protection mechanisms. Results show that an accuracy of 99% with AUC of 100$ was achieved when all the sensors were used. © The Author(s), under exclusive licence to Springer Nature Singapore Pte Ltd. 2024. | P22: Anomaly Detection; Drone Security; Machine Learning for Drones; Multi-Sensor Anomaly Detection; Sensor Fusion | Q22: 2-s2.0-85195944082
A23: Vithalani M.; Vaghela R.S.; Gohil J.A.; Gaylah K.D. | B23: Vithalani, Manav (59463957500); Vaghela, Ravirajsinh S. (57195488524); Gohil, Jaypalsinh A. (57215415981); Gaylah, Kwitee D. (58114309900) | C23: 59463957500; 57195488524; 57215415981; 58114309900 | D23: Drone Neutralization: A Comprehensive Framework for Detecting and Disrupting Malicious Drone Operations | E23: 2024 | F23: Lecture Notes in Networks and Systems | G23: 1095 LNNS | J23: 451 | K23: 460 | L23: 9 | M23: 10.1007/978-981-97-6318-4_35 | N23: https://www.scopus.com/inward/record.uri?eid=2-s2.0-85211320869&doi=10.1007%2f978-981-97-6318-4_35&partnerID=40&md5=cddd2b819c88abf76f339b00b5dfc136 | O23: With the increasing prevalence of drones and their susceptibility to wireless attacks, the need for effective countermeasures is crucial to safeguard civilian and military areas. This research paper presents a comprehensive methodology for neutralizing drones engaged in malicious activities, utilizing wireless network scanning, packet injection techniques, and cyber-attack approaches. The proposed framework encompasses four major steps: detection, reconnaissance, deauthentication, and gaining access or deactivation. Experimental testing demonstrates the successful implementation of the methodology, achieving results in detecting, disconnecting, and neutralizing drones. The framework offers distinct advantages over existing countermeasures, providing a proactive and real-time approach to countering the drone threat. This research contributes to the field of drone security by providing practical insights and tactics for mitigating potential risks posed by malicious drone operations, thus enhancing the overall protection of civilian and military sectors. © The Author(s), under exclusive license to Springer Nature Singapore Pte Ltd. 2024. | P23: Drone detection systems; Drone neutralization; Drone-to-ground communication; Drones security; Unmanned Aerial Vehicle (UAV); Wireless attacks | Q23: 2-s2.0-85211320869
A24: Adel A.; Jan T. | B24: Adel, Amr (57219892693); Jan, Tony (7004322283) | C24: 57219892693; 7004322283 | D24: Watch the Skies: A Study on Drone Attack Vectors, Forensic Approaches, and Persisting Security Challenges | E24: 2024 | F24: Future Internet | G24: 16 | H24: 7 | I24: 250 | M24: 10.3390/fi16070250 | N24: https://www.scopus.com/inward/record.uri?eid=2-s2.0-85199668263&doi=10.3390%2ffi16070250&partnerID=40&md5=da172daa57e7020632607b69caf26688 | O24: In the rapidly evolving landscape of drone technology, securing unmanned aerial vehicles (UAVs) presents critical challenges and demands unique solutions. This paper offers a thorough examination of the security requirements, threat models, and solutions pertinent to UAVs, emphasizing the importance of cybersecurity and drone forensics. This research addresses the unique requirements of UAV security, outlines various threat models, and explores diverse solutions to ensure data integrity. Drone forensics, a field dedicated to the investigation of security incidents involving UAVs, has been extensively examined and demonstrates its relevance in identifying attack origins or establishing accident causes. This paper further surveys artifacts, tools, and benchmark datasets that are critical in the domain of drone forensics, providing a comprehensive view of current capabilities. Acknowledging the ongoing challenges in UAV security, particularly given the pace of technological advancement and complex operational environments, this study underscores the need for increased collaboration, updated security protocols, and comprehensive regulatory frameworks. Ultimately, this research contributes to a deeper understanding of UAV cybersecurity and aids in fostering future research into the secure and reliable operation of drones. © 2024 by the authors. | P24: drone cybersecurity; drone forensics; forensic methodologies; security challenges; threat models; unmanned aerial vehicles (UAVs) | Q24: 2-s2.0-85199668263
A25: Selvan C.; Ragunathan A.; Ashwinkumar U.M. | B25: Selvan, C. (57191914884); Ragunathan, Aravindhan (58964794700); Ashwinkumar, U.M. (55201370200) | C25: 57191914884; 58964794700; 55201370200 | D25: Mitigating phishing threats in Unmanned Aircraft Systems (UAS) through multi-stage defense strategies | E25: 2024 | F25: Analyzing and Mitigating Security Risks in Cloud Computing | J25: 125 | K25: 162 | L25: 37 | M25: 10.4018/979-8-3693-3249-8.ch007 | N25: https://www.scopus.com/inward/record.uri?eid=2-s2.0-85189125432&doi=10.4018%2f979-8-3693-3249-8.ch007&partnerID=40&md5=8bd4b87dd3cfd9ac226aa627184b5be2 | O25: Phishing attacks, while more commonly associated with targeting individuals or organizations through traditional communication channels like email or social media, pose potential threats to unmanned aircraft systems (UAS) or drones. Although not as prevalent in this domain, there exist scenarios where phishing tactics could compromise UAS operations and data. Attackers might impersonate legitimate UAS entities, crafting emails that appear credible and relevant to UAS operations. A multi-stage approach incorporating natural language processing and machine learning is introduced to combat such threats. This approach employs techniques like conditional random field (CRF) and latent Dirichlet allocation (LDA) to detect phishing attacks and discern manipulated content. A novel web crawler utilizing web ontology language (OWL) is devised, leveraging semantic relationships to filter out fake sites from search results. The experimental results demonstrate the effectiveness of these methods in detecting and preventing phishing attacks across different platforms. © 2024, IGI Global. All rights reserved. | Q25: 2-s2.0-85189125432
A26: Ajakwe S.O.; Kim D.-S. | B26: Ajakwe, Simeon Okechukwu (57414321100); Kim, Dong-Seong (55586876300) | C26: 57414321100; 55586876300 | D26: Facets of security and safety problems and paradigms for smart aerial mobility and intelligent logistics | E26: 2024 | F26: IET Intelligent Transport Systems | G26: 18 | H26: S1 | J26: 2827 | K26: 2855 | L26: 28 | M26: 10.1049/itr2.12579 | N26: https://www.scopus.com/inward/record.uri?eid=2-s2.0-85209788941&doi=10.1049%2fitr2.12579&partnerID=40&md5=5b57fb249577ba50eccff2093249ae2d | O26: The use of unmanned aerial vehicles (UAVs) for smart and speedy logistics is still relatively nascent compared to traditional delivery methods. However, it is witnessing sporadic and steady growth due to booming demands, technological advancement, and regulatory support. The intelligence and integrity of UAV systems depend largely on the underlying cognitive and cybersecurity models, which serve as both eyes and brains to perceive and respond to the myriad of scenarios around them. Smart mobility and intelligent logistic ecosystems (SMiLE) are complex and advanced technological networks which are exposed to several issues. The incorporation of UAVs for priority logistics, thereby extending the coverage and capacity of SMiLE, further heightens these vulnerabilities and questions its security, safety, and sustainability. This review scrutinizes the significant security disruptions, smartness dynamics, and sundry developments for the sustainable deployment of UAVs as an aerial logistics-based vehicle. Using the PRISMA-SPIDER methodology, 157 articles were selected for quantitative analysis and 20 review articles for qualitative evaluation. Security and safety issues in UAVs cut across all the layers of logistics operations: components, communication, network architecture, navigation, supply chain etc. Expanding the capacity of SMiLE using UAV demands an intentional and incremental convergence-based integration of an agile explainable artificial framework for reliable and safety-conscious smart mobility, a scalable and tamperproof blockchain for multi-factor authentication, and a zero trust cybersecurity paradigm for inclusive enterprise-based authorization. © 2024 The Author(s). IET Intelligent Transport Systems published by John Wiley & Sons Ltd on behalf of The Institution of Engineering and Technology. | P26: artificial intelligence; blockchain; cyber attacks; drones; logistics; security; smart mobility; zero trust architecture | Q26: 2-s2.0-85209788941
